Workbook

Sheet INICIO
B7: PRECIOS DE REFERENCIA INTERNACIONAL
C9: PRECIOS | D9: Precios de referencia internacional por mercado relevante
C11: MRI | D11: Margen de referencia internacional
C13: TC | D13: Tasa de cambio de las monedas de los países de referencia
C15: PRI | D15: Cálculo del precio de referencia internacional
C17: FUENTES | D17: Fuentes internacionales de precios de medicamentos
C19: MARGEN | D19: Márgenes de ajuste de los precios internacionales
B21: Versión 2.0

Sheet PRECIOS
A1: ID | B1: ID MERCADO RELEVANTE | C1: ID MERCADO RELEVANTE Y PAÍS | D1: DESCRIPCIÓN MERCADO RELEVANTE | E1: MEDICAMENTO | F1: PAÍS | G1: FUENTE | H1: TIPO DE PRECIO | I1: PRIORIDAD TIPO DE PRECIO | J1: MONEDA | K1: PRECIO POR UNIDAD (MONEDA LOCAL) | L1: CANTIDAD PRINCIPIO ACTIVO | M1: UNIDAD DE MEDIDA (UM) | N1: PRECIO POR UM (MONEDA LOCAL) | O1: PRECIO POR UM (COP) | P1: SELECCIÓN TIPO DE PRECIO POR PAÍS | Q1: PRECIO POR UM AJUSTADO (COP) | R1: PRECIO DE REFERENCIA
A2: 1 | B2: 655 | C2: 655|BRASIL | D2: Asparaginasa -Líquido/Sólido - Inyectable | E2: ASPARAGINASA - Asparaginasa 10000UI/1U - LíqUIdo/Sólido - Inyectable - MEDAC | F2: BRASIL | G2: Banco de Preços Em Saude | H2: P. INSTITUCIONAL | I2: 2 | J2: BRL | K2: 1452.211 | L2: 10000 | M2: UI | N2: =+K2/L2 -> 0.1452211 | O2: =+VLOOKUP(J2,TC!$B$6:$C$17,2,0)*PRECIOS!N2 -> 122.40244 | P2: =IF(_xlfn.MINIFS($I:$I,$F:$F,F2,$E:$E,E2)=I2,"Si","No") -> Si | Q2: =+IF(I2=1,O2,IF(I2=2,O2/(1+MRI!$C$18),(O2/(1+MRI!$D$18))/(1+MRI!$C$18))) -> 111.71266 | R2: =+IF(P2="Si",Q2,"") -> 111.71266
A3: 2 | B3: 655 | C3: 655|BRASIL | D3: Asparaginasa -Líquido/Sólido - Inyectable | E3: ASPARAGINASA - Asparaginasa 10000UI/1U - LíqUIdo/Sólido - Inyectable- VHB MEDI SCIENCES | F3: BRASIL | G3: Banco de Preços Em Saude | H3: P. INSTITUCIONAL | I3: 2 | J3: BRL | K3: 1452.211 | L3: 10000 | M3: UI | N3: =+K3/L3 -> 0.1452211 | O3: =+VLOOKUP(J3,TC!$B$6:$C$17,2,0)*PRECIOS!N3 -> 122.40244 | P3: =IF(_xlfn.MINIFS($I:$I,$F:$F,F3,$E:$E,E3)=I3,"Si","No") -> Si | Q3: =+IF(I3=1,O3,IF(I3=2,O3/(1+MRI!$C$18),(O3/(1+MRI!$D$18))/(1+MRI!$C$18))) -> 111.71266 | R3: =+IF(P3="Si",Q3,"") -> 111.71266
A4: 3 | B4: 655 | C4: 655|BRASIL | D4: Asparaginasa -Líquido/Sólido - Inyectable | E4: SPECTRILA - Asparaginasa 10000UI/1U - LíqUIdo/Sólido - Inyectable - MEDAC | F4: BRASIL | G4: CMED-ANVISA | H4: P. FABRICANTE | I4: 1 | J4: BRL | K4: 1613.46 | L4: 10000 | M4: UI | N4: =+K4/L4 -> 0.161346 | O4: =+VLOOKUP(J4,TC!$B$6:$C$17,2,0)*PRECIOS!N4 -> 135.99363 | P4: =IF(_xlfn.MINIFS($I:$I,$F:$F,F4,$E:$E,E4)=I4,"Si","No") -> Si | Q4: =+IF(I4=1,O4,IF(I4=2,O4/(1+MRI!$C$18),(O4/(1+MRI!$D$18))/(1+MRI!$C$18))) -> 135.99363 | R4: =+IF(P4="Si",Q4,"") -> 135.99363
A5: 4 | B5: 655 | C5: 655|BRASIL | D5: Asparaginasa -Líquido/Sólido - Inyectable | E5: SPECTRILA - Asparaginasa 10000UI/1U - LíqUIdo/Sólido - Inyectable - MEDAC | F5: BRASIL | G5: CMED-ANVISA | H5: P. INSTITUCIONAL | I5: 2 | J5: BRL | K5: 1266.08 | L5: 10000 | M5: UI | N5: =+K5/L5 -> 0.126608 | O5: =+VLOOKUP(J5,TC!$B$6:$C$17,2,0)*PRECIOS!N5 -> 106.71402 | P5: =IF(_xlfn.MINIFS($I:$I,$F:$F,F5,$E:$E,E5)=I5,"Si","No") -> No | Q5: =+IF(I5=1,O5,IF(I5=2,O5/(1+MRI!$C$18),(O5/(1+MRI!$D$18))/(1+MRI!$C$18))) -> 97.394358 | R5: =+IF(P5="Si",Q5,"")
A6: 5 | B6: 655 | C6: 655|CHILE | D6: Asparaginasa -Líquido/Sólido - Inyectable | E6: SPECTRILA - Asparaginasa 10000UI/1U - LíqUIdo/Sólido - Inyectable - MEDAC | F6: CHILE | G6: Central de abastecimiento del Sistema Nacional de servicios de Salud - CENABAST | H6: P. INSTITUCIONAL | I6: 2 | J6: CLP | K6: 252000 | L6: 10000 | M6: UI | N6: =+K6/L6 -> 25.2 | O6: =+VLOOKUP(J6,TC!$B$6:$C$17,2,0)*PRECIOS!N6 -> 126.64846 | P6: =IF(_xlfn.MINIFS($I:$I,$F:$F,F6,$E:$E,E6)=I6,"Si","No") -> Si | Q6: =+IF(I6=1,O6,IF(I6=2,O6/(1+MRI!$C$18),(O6/(1+MRI!$D$18))/(1+MRI!$C$18))) -> 115.58786 | R6: =+IF(P6="Si",Q6,"") -> 115.58786
A7: 6 | B7: 655 | C7: 655|ECUADOR | D7: Asparaginasa -Líquido/Sólido - Inyectable | E7: ASPARAGINASA - Asparaginasa 10000UI/1U - LíqUIdo/Sólido - Inyectable - MEDAC | F7: ECUADOR | G7: Consejo Nacional de Fijación y revisión de Precios de Medicamentos de Uso Humano | H7: P. CONSUMIDOR | I7: 3 | J7: USD | K7: 77.14 | L7: 10000 | M7: UI | N7: =+K7/L7 -> 0.007714 | O7: =+VLOOKUP(J7,TC!$B$6:$C$17,2,0)*PRECIOS!N7 -> 33.105636 | P7: =IF(_xlfn.MINIFS($I:$I,$F:$F,F7,$E:$E,E7)=I7,"Si","No") -> No | Q7: =+IF(I7=1,O7,IF(I7=2,O7/(1+MRI!$C$18),(O7/(1+MRI!$D$18))/(1+MRI!$C$18))) -> 25.308254 | R7: =+IF(P7="Si",Q7,"")
A8: 7 | B8: 655 | C8: 655|ECUADOR | D8: Asparaginasa -Líquido/Sólido - Inyectable | E8: ASPARAGINASA - Asparaginasa 10000UI/1U - LíqUIdo/Sólido - Inyectable - MEDAC | F8: ECUADOR | G8: Sistema Oficial de Contratación Pública | H8: P. INSTITUCIONAL | I8: 2 | J8: USD | K8: 59.19 | L8: 10000 | M8: UI | N8: =+K8/L8 -> 0.005919 | O8: =+VLOOKUP(J8,TC!$B$6:$C$17,2,0)*PRECIOS!N8 -> 25.40216 | P8: =IF(_xlfn.MINIFS($I:$I,$F:$F,F8,$E:$E,E8)=I8,"Si","No") -> Si | Q8: =+IF(I8=1,O8,IF(I8=2,O8/(1+MRI!$C$18),(O8/(1+MRI!$D$18))/(1+MRI!$C$18))) -> 23.18371 | R8: =+IF(P8="Si",Q8,"") -> 23.18371
A9: 8 | B9: 655 | C9: 655|ECUADOR | D9: Asparaginasa -Líquido/Sólido - Inyectable | E9: ASPARAGINASA - Asparaginasa 10000UI/1U - LíqUIdo/Sólido - Inyectable- VHB MEDI SCIENCES | F9: ECUADOR | G9: Consejo Nacional de Fijación y revisión de Precios de Medicamentos de Uso Humano | H9: P. CONSUMIDOR | I9: 3 | J9: USD | K9: 77.14 | L9: 10000 | M9: UI | N9: =+K9/L9 -> 0.007714 | O9: =+VLOOKUP(J9,TC!$B$6:$C$17,2,0)*PRECIOS!N9 -> 33.105636 | P9: =IF(_xlfn.MINIFS($I:$I,$F:$F,F9,$E:$E,E9)=I9,"Si","No") -> No | Q9: =+IF(I9=1,O9,IF(I9=2,O9/(1+MRI!$C$18),(O9/(1+MRI!$D$18))/(1+MRI!$C$18))) -> 25.308254 | R9: =+IF(P9="Si",Q9,"")
A10: 9 | B10: 655 | C10: 655|ECUADOR | D10: Asparaginasa -Líquido/Sólido - Inyectable | E10: ASPARAGINASA - Asparaginasa 10000UI/1U - LíqUIdo/Sólido - Inyectable- VHB MEDI SCIENCES | F10: ECUADOR | G10: Sistema Oficial de Contratación Pública | H10: P. INSTITUCIONAL | I10: 2 | J10: USD | K10: 59.19 | L10: 10000 | M10: UI | N10: =+K10/L10 -> 0.005919 | O10: =+VLOOKUP(J10,TC!$B$6:$C$17,2,0)*PRECIOS!N10 -> 25.40216 | P10: =IF(_xlfn.MINIFS($I:$I,$F:$F,F10,$E:$E,E10)=I10,"Si","No") -> Si | Q10: =+IF(I10=1,O10,IF(I10=2,O10/(1+MRI!$C$18),(O10/(1+MRI!$D$18))/(1+MRI!$C$18))) -> 23.18371 | R10: =+IF(P10="Si",Q10,"") -> 23.18371
A11: 10 | B11: 655 | C11: 655|ECUADOR | D11: Asparaginasa -Líquido/Sólido - Inyectable | E11: KIDROLASE - Asparaginasa 10000UI/1U - LíqUIdo/Sólido - Inyectable - EUSAPHARMA | F11: ECUADOR | G11: Consejo Nacional de Fijación y revisión de Precios de Medicamentos de Uso Humano | H11: P. CONSUMIDOR | I11: 3 | J11: USD | K11: 77.14 | L11: 10000 | M11: UI | N11: =+K11/L11 -> 0.007714 | O11: =+VLOOKUP(J11,TC!$B$6:$C$17,2,0)*PRECIOS!N11 -> 33.105636 | P11: =IF(_xlfn.MINIFS($I:$I,$F:$F,F11,$E:$E,E11)=I11,"Si","No") -> Si | Q11: =+IF(I11=1,O11,IF(I11=2,O11/(1+MRI!$C$18),(O11/(1+MRI!$D$18))/(1+MRI!$C$18))) -> 25.308254 | R11: =+IF(P11="Si",Q11,"") -> 25.308254
A12: 11 | B12: 655 | C12: 655|ECUADOR | D12: Asparaginasa -Líquido/Sólido - Inyectable | E12: SPECTRILA - Asparaginasa 10000UI/1U - LíqUIdo/Sólido - Inyectable - MEDAC | F12: ECUADOR | G12: Consejo Nacional de Fijación y revisión de Precios de Medicamentos de Uso Humano | H12: P. CONSUMIDOR | I12: 3 | J12: USD | K12: 77.14 | L12: 10000 | M12: UI | N12: =+K12/L12 -> 0.007714 | O12: =+VLOOKUP(J12,TC!$B$6:$C$17,2,0)*PRECIOS!N12 -> 33.105636 | P12: =IF(_xlfn.MINIFS($I:$I,$F:$F,F12,$E:$E,E12)=I12,"Si","No") -> Si | Q12: =+IF(I12=1,O12,IF(I12=2,O12/(1+MRI!$C$18),(O12/(1+MRI!$D$18))/(1+MRI!$C$18))) -> 25.308254 | R12: =+IF(P12="Si",Q12,"") -> 25.308254
A13: 12 | B13: 655 | C13: 655|ITALIA | D13: Asparaginasa -Líquido/Sólido - Inyectable | E13: SPECTRILA - Asparaginasa 10000UI/1U - LíqUIdo/Sólido - Inyectable - MEDAC | F13: ITALIA | G13: Agenzia Italiana del Farmaco | H13: P. CONSUMIDOR | I13: 3 | J13: EUR | K13: 886.53 | L13: 10000 | M13: UI | N13: =+K13/L13 -> 0.088653 | O13: =+VLOOKUP(J13,TC!$B$6:$C$17,2,0)*PRECIOS!N13 -> 405.71168 | P13: =IF(_xlfn.MINIFS($I:$I,$F:$F,F13,$E:$E,E13)=I13,"Si","No") -> No | Q13: =+IF(I13=1,O13,IF(I13=2,O13/(1+MRI!$C$18),(O13/(1+MRI!$D$18))/(1+MRI!$C$18))) -> 310.15426 | R13: =+IF(P13="Si",Q13,"")
... A125: 124 | B125: 838 | C125: 838|MÉXICO | D125: Ioversol -Líquido/Sólido - Inyectable | E125: Ioversol 33900mg/50ml (678mg/1ml) | F125: MÉXICO | G125: Plataforma Integral CompraNet | H125: P. INSTITUCIONAL | I125: 2 | J125: MXN | K125: 985 | L125: 33900 | M125: mg | N125: =+K125/L125 -> 0.029056047 | O125: =+VLOOKUP(J125,TC!$B$6:$C$17,2,0)*PRECIOS!N125 -> 6.6023561 | P125: =IF(_xlfn.MINIFS($I:$I,$F:$F,F125,$E:$E,E125)=I125,"Si","No") -> Si | Q125: =+IF(I125=1,O125,IF(I125=2,O125/(1+MRI!$C$18),(O125/(1+MRI!$D$18))/(1+MRI!$C$18))) -> 6.0257519 | R125: =+IF(P125="Si",Q125,"") -> 6.0257519
A126: 125 | B126: 483a | C126: 483a|BRASIL | D126: Inmunoglobulina Humana Normal (admin. extravascular) -Líquido/Sólido - Inyectable | E126: BERIGLOBINA - Inmunoglobulina Humana Normal 320mg/2ml (160mg/1ml) - Líquido/Sólido - Inyectable - CSL | F126: BRASIL | G126: CMED-ANVISA | H126: P. CONSUMIDOR | I126: 3 | J126: BRL | K126: 47.75 | L126: 320 | M126: mg | N126: =+K126/L126 -> 0.14921875 | O126: =+VLOOKUP(J126,TC!$B$6:$C$17,2,0)*PRECIOS!N126 -> 125.77194 | P126: =IF(_xlfn.MINIFS($I:$I,$F:$F,F126,$E:$E,E126)=I126,"Si","No") -> No | Q126: =+IF(I126=1,O126,IF(I126=2,O126/(1+MRI!$C$18),(O126/(1+MRI!$D$18))/(1+MRI!$C$18))) -> 96.148827 | R126: =+IF(P126="Si",Q126,"")
A127: 126 | B127: 483a | C127: 483a|BRASIL | D127: Inmunoglobulina Humana Normal (admin. extravascular) -Líquido/Sólido - Inyectable | E127: BERIGLOBINA - Inmunoglobulina Humana Normal 320mg/2ml (160mg/1ml) - Líquido/Sólido - Inyectable - CSL | F127: BRASIL | G127: CMED-ANVISA | H127: P. FABRICANTE | I127: 1 | J127: BRL | K127: 34.54 | L127: 320 | M127: mg | N127: =+K127/L127 -> 0.1079375 | O127: =+VLOOKUP(J127,TC!$B$6:$C$17,2,0)*PRECIOS!N127 -> 90.977229 | P127: =IF(_xlfn.MINIFS($I:$I,$F:$F,F127,$E:$E,E127)=I127,"Si","No") -> Si | Q127: =+IF(I127=1,O127,IF(I127=2,O127/(1+MRI!$C$18),(O127/(1+MRI!$D$18))/(1+MRI!$C$18))) -> 90.977229 | R127: =+IF(P127="Si",Q127,"") -> 90.977229
A128: 127 | B128: 483a | C128: 483a|BRASIL | D128: Inmunoglobulina Humana Normal (admin. extravascular) -Líquido/Sólido - Inyectable | E128: BERIGLOBINA - Inmunoglobulina Humana Normal 320mg/2ml (160mg/1ml) - Líquido/Sólido - Inyectable - CSL | F128: BRASIL | G128: CMED-ANVISA | H128: P. INSTITUCIONAL | I128: 2 | J128: BRL | K128: 27.1 | L128: 320 | M128: mg | N128: =+K128/L128 -> 0.0846875 | O128: =+VLOOKUP(J128,TC!$B$6:$C$17,2,0)*PRECIOS!N128 -> 71.380513 | P128: =IF(_xlfn.MINIFS($I:$I,$F:$F,F128,$E:$E,E128)=I128,"Si","No") -> No | Q128: =+IF(I128=1,O128,IF(I128=2,O128/(1+MRI!$C$18),(O128/(1+MRI!$D$18))/(1+MRI!$C$18))) -> 65.146632 | R128: =+IF(P128="Si",Q128,"")
A129: 128 | B129: 483a | C129: 483a|BRASIL | D129: Inmunoglobulina Humana Normal (admin. extravascular) -Líquido/Sólido - Inyectable | E129: CUVITRU - Inmunoglobulina Humana 1000mg/5ml - Líquido/Sólido - Inyectable x 1 - BAXALTA | F129: BRASIL | G129: CMED-ANVISA | H129: P. CONSUMIDOR | I129: 3 | J129: BRL | K129: 457.56 | L129: 1000 | M129: mg | N129: =+K129/L129 -> 0.45756 | O129: =+VLOOKUP(J129,TC!$B$6:$C$17,2,0)*PRECIOS!N129 -> 385.66338 | P129: =IF(_xlfn.MINIFS($I:$I,$F:$F,F129,$E:$E,E129)=I129,"Si","No") -> No | Q129: =+IF(I129=1,O129,IF(I129=2,O129/(1+MRI!$C$18),(O129/(1+MRI!$D$18))/(1+MRI!$C$18))) -> 294.82794 | R129: =+IF(P129="Si",Q129,"")
A130: 129 | B130: 483a | C130: 483a|BRASIL | D130: Inmunoglobulina Humana Normal (admin. extravascular) -Líquido/Sólido - Inyectable | E130: CUVITRU - Inmunoglobulina Humana 1000mg/5ml - Líquido/Sólido - Inyectable x 1 - BAXALTA | F130: BRASIL | G130: CMED-ANVISA | H130: P. FABRICANTE | I130: 1 | J130: BRL | K130: 330.98 | L130: 1000 | M130: mg | N130: =+K130/L130 -> 0.33098 | O130: =+VLOOKUP(J130,TC!$B$6:$C$17,2,0)*PRECIOS!N130 -> 278.97295 | P130: =IF(_xlfn.MINIFS($I:$I,$F:$F,F130,$E:$E,E130)=I130,"Si","No") -> Si | Q130: =+IF(I130=1,O130,IF(I130=2,O130/(1+MRI!$C$18),(O130/(1+MRI!$D$18))/(1+MRI!$C$18))) -> 278.97295 | R130: =+IF(P130="Si",Q130,"") -> 278.97295
A131: 130 | B131: 483a | C131: 483a|BRASIL | D131: Inmunoglobulina Humana Normal (admin. extravascular) -Líquido/Sólido - Inyectable | E131: CUVITRU - Inmunoglobulina Humana 1000mg/5ml - Líquido/Sólido - Inyectable x 1 - BAXALTA | F131: BRASIL | G131: CMED-ANVISA | H131: P. INSTITUCIONAL | I131: 2 | J131: BRL | K131: 259.72 | L131: 1000 | M131: mg | N131: =+K131/L131 -> 0.25972 | O131: =+VLOOKUP(J131,TC!$B$6:$C$17,2,0)*PRECIOS!N131 -> 218.91007 | P131: =IF(_xlfn.MINIFS($I:$I,$F:$F,F131,$E:$E,E131)=I131,"Si","No") -> No | Q131: =+IF(I131=1,O131,IF(I131=2,O131/(1+MRI!$C$18),(O131/(1+MRI!$D$18))/(1+MRI!$C$18))) -> 199.79198 | R131: =+IF(P131="Si",Q131,"")
A132: 131 | B132: 483a | C132: 483a|BRASIL | D132: Inmunoglobulina Humana Normal (admin. extravascular) -Líquido/Sólido - Inyectable | E132: CUVITRU - Inmunoglobulina Humana 4000mg/20ml - Líquido/Sólido - Inyectable - BAXALTA | F132: BRASIL | G132: CMED-ANVISA | H132: P. CONSUMIDOR | I132: 3 | J132: BRL | K132: 1830.28 | L132: 4000 | M132: mg | N132: =+K132/L132 -> 0.45757 | O132: =+VLOOKUP(J132,TC!$B$6:$C$17,2,0)*PRECIOS!N132 -> 385.67181 | P132: =IF(_xlfn.MINIFS($I:$I,$F:$F,F132,$E:$E,E132)=I132,"Si","No") -> No | Q132: =+IF(I132=1,O132,IF(I132=2,O132/(1+MRI!$C$18),(O132/(1+MRI!$D$18))/(1+MRI!$C$18))) -> 294.83439 | R132: =+IF(P132="Si",Q132,"")
A133: 132 | B133: 483a | C133: 483a|BRASIL | D133: Inmunoglobulina Humana Normal (admin. extravascular) -Líquido/Sólido - Inyectable | E133: CUVITRU - Inmunoglobulina Humana 4000mg/20ml - Líquido/Sólido - Inyectable - BAXALTA | F133: BRASIL | G133: CMED-ANVISA | H133: P. FABRICANTE | I133: 1 | J133: BRL | K133: 1323.95 | L133: 4000 | M133: mg | N133: =+K133/L133 -> 0.3309875 | O133: =+VLOOKUP(J133,TC!$B$6:$C$17,2,0)*PRECIOS!N133 -> 278.97928 | P133: =IF(_xlfn.MINIFS($I:$I,$F:$F,F133,$E:$E,E133)=I133,"Si","No") -> Si | Q133: =+IF(I133=1,O133,IF(I133=2,O133/(1+MRI!$C$18),(O133/(1+MRI!$D$18))/(1+MRI!$C$18))) -> 278.97928 | R133: =+IF(P133="Si",Q133,"") -> 278.97928
A134: 133 | B134: 483a | C134: 483a|BRASIL | D134: Inmunoglobulina Humana Normal (admin. extravascular) -Líquido/Sólido - Inyectable | E134: CUVITRU - Inmunoglobulina Humana 4000mg/20ml - Líquido/Sólido - Inyectable - BAXALTA | F134: BRASIL | G134: CMED-ANVISA | H134: P. INSTITUCIONAL | I134: 2 | J134: BRL | K134: 1038.9 | L134: 4000 | M134: mg | N134: =+K134/L134 -> 0.259725 | O134: =+VLOOKUP(J134,TC!$B$6:$C$17,2,0)*PRECIOS!N134 -> 218.91429 | P134: =IF(_xlfn.MINIFS($I:$I,$F:$F,F134,$E:$E,E134)=I134,"Si","No") -> No | Q134: =+IF(I134=1,O134,IF(I134=2,O134/(1+MRI!$C$18),(O134/(1+MRI!$D$18))/(1+MRI!$C$18))) -> 199.79582 | R134: =+IF(P134="Si",Q134,"")
A135: 134 | B135: 483a | C135: 483a|BRASIL | D135: Inmunoglobulina Humana Normal (admin. extravascular) -Líquido/Sólido - Inyectable | E135: CUVITRU - Inmunoglobulina Humana Normal 1000mg/5ml (200mg/1ml) - Líquido/Sólido - Inyectable - BAXALTA | F135: BRASIL | G135: CMED-ANVISA | H135: P. CONSUMIDOR | I135: 3 | J135: BRL | K135: 457.56 | L135: 1000 | M135: mg | N135: =+K135/L135 -> 0.45756 | O135: =+VLOOKUP(J135,TC!$B$6:$C$17,2,0)*PRECIOS!N135 -> 385.66338 | P135: =IF(_xlfn.MINIFS($I:$I,$F:$F,F135,$E:$E,E135)=I135,"Si","No") -> No | Q135: =+IF(I135=1,O135,IF(I135=2,O135/(1+MRI!$C$18),(O135/(1+MRI!$D$18))/(1+MRI!$C$18))) -> 294.82794 | R135: =+IF(P135="Si",Q135,"")
A136: 135 | B136: 483a | C136: 483a|BRASIL | D136: Inmunoglobulina Humana Normal (admin. extravascular) -Líquido/Sólido - Inyectable | E136: CUVITRU - Inmunoglobulina Humana Normal 1000mg/5ml (200mg/1ml) - Líquido/Sólido - Inyectable - BAXALTA | F136: BRASIL | G136: CMED-ANVISA | H136: P. FABRICANTE | I136: 1 | J136: BRL | K136: 330.98 | L136: 1000 | M136: mg | N136: =+K136/L136 -> 0.33098 | O136: =+VLOOKUP(J136,TC!$B$6:$C$17,2,0)*PRECIOS!N136 -> 278.97295 | P136: =IF(_xlfn.MINIFS($I:$I,$F:$F,F136,$E:$E,E136)=I136,"Si","No") -> Si | Q136: =+IF(I136=1,O136,IF(I136=2,O136/(1+MRI!$C$18),(O136/(1+MRI!$D$18))/(1+MRI!$C$18))) -> 278.97295 | R136: =+IF(P136="Si",Q136,"") -> 278.97295
A137: 136 | B137: 483a | C137: 483a|BRASIL | D137: Inmunoglobulina Humana Normal (admin. extravascular) -Líquido/Sólido - Inyectable | E137: CUVITRU - Inmunoglobulina Humana Normal 1000mg/5ml (200mg/1ml) - Líquido/Sólido - Inyectable - BAXALTA | F137: BRASIL | G137: CMED-ANVISA | H137: P. INSTITUCIONAL | I137: 2 | J137: BRL | K137: 259.72 | L137: 1000 | M137: mg | N137: =+K137/L137 -> 0.25972 | O137: =+VLOOKUP(J137,TC!$B$6:$C$17,2,0)*PRECIOS!N137 -> 218.91007 | P137: =IF(_xlfn.MINIFS($I:$I,$F:$F,F137,$E:$E,E137)=I137,"Si","No") -> No | Q137: =+IF(I137=1,O137,IF(I137=2,O137/(1+MRI!$C$18),(O137/(1+MRI!$D$18))/(1+MRI!$C$18))) -> 199.79198 | R137: =+IF(P137="Si",Q137,"")
... A556: 555 | B556: 543b | C556: 543b|BRASIL | D556: Inmunoglobulina Humana Normal (admin. intravascular) (IgG, IgM, IgA) -Líquido/Sólido - Inyectable | E556: PENTAGLOBIN - Inmunoglobulina Humana 380mg/10ml - Líquido/Sólido - Inyectable x 1 - BIOTEST | F556: BRASIL | G556: CMED-ANVISA | H556: P. INSTITUCIONAL | I556: 2 | J556: BRL | K556: 136.84 | L556: 380 | M556: mg | N556: =+K556/L556 -> 0.36010526 | O556: =+VLOOKUP(J556,TC!$B$6:$C$17,2,0)*PRECIOS!N556 -> 303.52175 | P556: =IF(_xlfn.MINIFS($I:$I,$F:$F,F556,$E:$E,E556)=I556,"Si","No") -> No | Q556: =+IF(I556=1,O556,IF(I556=2,O556/(1+MRI!$C$18),(O556/(1+MRI!$D$18))/(1+MRI!$C$18))) -> 277.01426 | R556: =+IF(P556="Si",Q556,"")

Sheet MRI
A1: Margen de Referencia Internacional
A2: 1. De los márgenes disponibles por país, se toma el margen más alto como referencia para el país.
A3: 2. Para definir el Margen de Referencia Internacional (MRI), se calcula el promedio simple de los márgenes disponibles.
B5: PAÍS | C5: PF → PM | D5: PM → PC
B6: ALEMANIA | C6: 0.21
B7: AUSTRALIA | C7: 0.0752 | D7: 0.0462
B8: BRASIL | C8: 0.12 | D8: 0.1
B9: CANADÁ | C9: 0.09
B10: ESPAÑA | C10: 0.076 | D10: 0.203
B11: FRANCIA | C11: 0.0693 | D11: 0.0307
B12: GRECIA | C12: 0.054 | D12: 0.35
B13: INDIA | C13: 0.08 | D13: 0.16
B14: PERÚ | D14: 0.25
B15: PORTUGAL | C15: 0.0724 | D15: 0.1094
B16: SURÁFRICA | C16: 0.11 | D16: 0.49540678
B18: MRI | C18: =AVERAGE(C6:C16) -> 0.09569 | D18: =AVERAGE(D6:D16) -> 0.19385631

Sheet TC
A1: Tasa de cambio
A2: Valor nominal de la moneda de los países de referencia expresada en pesos colombianos publicada por el Banco de la República
A3: El periodo de referencia corresponde al 1 de enero de 2022 al 31 de diciembre de 2023
B5: MONEDA | C5: TASA DE CAMBIO
B6: AUD | C6: 2914.5175
B7: BRL | C7: 842.86952
B8: CAD | C8: 3236.7256
B9: CLP | C9: 5.0257325
B10: EUR | C10: 4576.401
B11: GBP | C11: 5312.4925
B12: INR | C12: 53.30004
B13: MXN | C13: 227.2283
B14: NOK | C14: 427.18185
B15: PEN | C15: 1130.8437
B16: USD | C16: 4291.6303
B17: ZAR | C17: 247.82295

Sheet PRI
A1: Precio de Referencia Internacional
A2: Seleccione el mercado relevante de la lista desplegable:
C3: MERCADO RELEVANTE: | D3: Asparaginasa -Líquido/Sólido - Inyectable
C4: ID MERCADO RELEVANTE: | D4: =+_xlfn.XLOOKUP(D3,PRECIOS!$D:$D,PRECIOS!$B:$B,,0) -> 655
C6: PAÍS | D6: PRECIO DE REFERENCIA POR PAÍS | E6: UNIDAD DE MEDIDA | G6: DESCRIPCIÓN MERCADO RELEVANTE
C7: ALEMANIA | D7: =IFERROR(AVERAGEIF(PRECIOS!C:C,PRI!$D$4&"|"&PRI!C7,PRECIOS!R:R),"") | E7: =IF(D7="","",VLOOKUP($D$4,PRECIOS!$B:$M,12,0)) | G7: Asparaginasa -Líquido/Sólido - Inyectable
C8: AUSTRALIA | D8: =IFERROR(AVERAGEIF(PRECIOS!C:C,PRI!$D$4&"|"&PRI!C8,PRECIOS!R:R),"") | E8: =IF(D8="","",VLOOKUP($D$4,PRECIOS!$B:$M,12,0)) | G8: Ioversol -Líquido/Sólido - Inyectable
C9: BRASIL | D9: =IFERROR(AVERAGEIF(PRECIOS!C:C,PRI!$D$4&"|"&PRI!C9,PRECIOS!R:R),"") -> 119.80631 | E9: =IF(D9="","",VLOOKUP($D$4,PRECIOS!$B:$M,12,0)) -> UI | G9: Inmunoglobulina Humana Normal (admin. extravascular) -Líquido/Sólido - Inyectable
C10: CANADA | D10: =IFERROR(AVERAGEIF(PRECIOS!C:C,PRI!$D$4&"|"&PRI!C10,PRECIOS!R:R),"") | E10: =IF(D10="","",VLOOKUP($D$4,PRECIOS!$B:$M,12,0)) | G10: Inmunoglobulina Humana Normal (admin. extravascular) con Hialuronidasa -Líquido/Sólido - Inyectable
C11: CHILE | D11: =IFERROR(AVERAGEIF(PRECIOS!C:C,PRI!$D$4&"|"&PRI!C11,PRECIOS!R:R),"") -> 115.58786 | E11: =IF(D11="","",VLOOKUP($D$4,PRECIOS!$B:$M,12,0)) -> UI | G11: Inmunoglobulina Humana Normal (admin. intravascular) (con proporción de IgG mayor al 95%) -Líquido/Sólido - Inyectable
C12: ECUADOR | D12: =IFERROR(AVERAGEIF(PRECIOS!C:C,PRI!$D$4&"|"&PRI!C12,PRECIOS!R:R),"") -> 24.245982 | E12: =IF(D12="","",VLOOKUP($D$4,PRECIOS!$B:$M,12,0)) -> UI | G12: Inmunoglobulina Humana Normal (admin. intravascular) (IgG, IgM, IgA) -Líquido/Sólido - Inyectable
C13: EE.UU. | D13: =IFERROR(AVERAGEIF(PRECIOS!C:C,PRI!$D$4&"|"&PRI!C13,PRECIOS!R:R),"") | E13: =IF(D13="","",VLOOKUP($D$4,PRECIOS!$B:$M,12,0))
C14: ESPAÑA | D14: =IFERROR(AVERAGEIF(PRECIOS!C:C,PRI!$D$4&"|"&PRI!C14,PRECIOS!R:R),"") | E14: =IF(D14="","",VLOOKUP($D$4,PRECIOS!$B:$M,12,0))
C15: FRANCIA | D15: =IFERROR(AVERAGEIF(PRECIOS!C:C,PRI!$D$4&"|"&PRI!C15,PRECIOS!R:R),"") | E15: =IF(D15="","",VLOOKUP($D$4,PRECIOS!$B:$M,12,0))
C16: GRECIA | D16: =IFERROR(AVERAGEIF(PRECIOS!C:C,PRI!$D$4&"|"&PRI!C16,PRECIOS!R:R),"") | E16: =IF(D16="","",VLOOKUP($D$4,PRECIOS!$B:$M,12,0))
C17: ITALIA | D17: =IFERROR(AVERAGEIF(PRECIOS!C:C,PRI!$D$4&"|"&PRI!C17,PRECIOS!R:R),"") -> 245.82596 | E17: =IF(D17="","",VLOOKUP($D$4,PRECIOS!$B:$M,12,0)) -> UI
C18: INDIA | D18: =IFERROR(AVERAGEIF(PRECIOS!C:C,PRI!$D$4&"|"&PRI!C18,PRECIOS!R:R),"") | E18: =IF(D18="","",VLOOKUP($D$4,PRECIOS!$B:$M,12,0))
C19: MÉXICO | D19: =IFERROR(AVERAGEIF(PRECIOS!C:C,PRI!$D$4&"|"&PRI!C19,PRECIOS!R:R),"") | E19: =IF(D19="","",VLOOKUP($D$4,PRECIOS!$B:$M,12,0))
C20: NORUEGA | D20: =IFERROR(AVERAGEIF(PRECIOS!C:C,PRI!$D$4&"|"&PRI!C20,PRECIOS!R:R),"") | E20: =IF(D20="","",VLOOKUP($D$4,PRECIOS!$B:$M,12,0))
C21: PANAMÁ | D21: =IFERROR(AVERAGEIF(PRECIOS!C:C,PRI!$D$4&"|"&PRI!C21,PRECIOS!R:R),"") | E21: =IF(D21="","",VLOOKUP($D$4,PRECIOS!$B:$M,12,0))
C22: PERÚ | D22: =IFERROR(AVERAGEIF(PRECIOS!C:C,PRI!$D$4&"|"&PRI!C22,PRECIOS!R:R),"") | E22: =IF(D22="","",VLOOKUP($D$4,PRECIOS!$B:$M,12,0))
C23: PORTUGAL | D23: =IFERROR(AVERAGEIF(PRECIOS!C:C,PRI!$D$4&"|"&PRI!C23,PRECIOS!R:R),"") | E23: =IF(D23="","",VLOOKUP($D$4,PRECIOS!$B:$M,12,0))
C24: REINO UNIDO | D24: =IFERROR(AVERAGEIF(PRECIOS!C:C,PRI!$D$4&"|"&PRI!C24,PRECIOS!R:R),"") -> 218.18412 | E24: =IF(D24="","",VLOOKUP($D$4,PRECIOS!$B:$M,12,0)) -> UI
C25: SUDAFRICA | D25: =IFERROR(AVERAGEIF(PRECIOS!C:C,PRI!$D$4&"|"&PRI!C25,PRECIOS!R:R),"") | E25: =IF(D25="","",VLOOKUP($D$4,PRECIOS!$B:$M,12,0))
C27: PRI 20 | D27: =IF(COUNT(D7:D25)<4,"NO HAY SUFICIENTES FUENTES PARA CALCULAR PRI",ROUND(PERCENTILE(D7:D25,0.2),2)) -> 97.32 | E27: =IF(D27="","",VLOOKUP($D$4,PRECIOS!$B:$M,12,0)) -> UI
C28: Margen de ajuste | D28: =+MRI!$C$18 -> 0.09569
C29: Precio máximo de venta | D29: =IFERROR(ROUND($D$27*(1+$D$28),2),D27) -> 106.63 | E29: =IF(D29="","",VLOOKUP($D$4,PRECIOS!$B:$M,12,0)) -> UI

Sheet FUENTES
A1: Fuentes internacionales de precios de medicamentos
A3: Última actualización: Abril de 2024
A4: No. | B4: País | C4: Fuente | D4: Enlace
A5: 1 | B5: ALEMANIA | C5: DIMDI (Institute of Medical Documentation and Information) | D5: https://www.bfarm.de/DE/Arzneimittel/Arzneimittelinformationen/Festbetraege-und-Zuzahlungen/Festbetraege/_node.html
A6: 2 | B6: AUSTRALIA | C6: National Blood Authority | D6: https://blood.gov.au/national-product-price-list
A7: 3 | B7: AUSTRALIA | C7: Pharmaceutical Benefits Scheme | D7: https://www.pbs.gov.au/info/industry/pricing/ex-manufacturer-price
A8: 4 | B8: BRASIL | C8: Banco de Preços Em Saude | D8: http://bps.saude.gov.br/login.jsf
A9: 5 | B9: BRASIL | C9: CMED-ANVISA | D9: https://www.gov.br/anvisa/pt-br/assuntos/medicamentos/cmed/precos
A10: 6 | B10: CANADA | C10: Ontario Drug Benefit Formulary/Comparative Drug Index | D10: https://www.formulary.health.gov.on.ca/formulary/
A11: 7 | B11: CANADA | C11: Ontario Drug Benefit Formulary/Comparative Drug Index - EXCEPTIONAL ACCESS PROGRAM | D11: http://www.health.gov.on.ca/en/pro/programs/drugs/odbf/odbf_except_access.aspx
A12: 8 | B12: CANADA | C12: Regie de lássurance maladie du Quebec | D12: https://www.ramq.gouv.qc.ca/en/about-us/list-medications
A13: 9 | B13: CHILE | C13: Portal de compras públicas (Chilecompra) | D13: https://www.mercadopublico.cl/Portal/Modules/Site/Busquedas/BuscadorAvanzado.aspx?qs=1
A14: 10 | B14: ECUADOR | C14: Consejo Nacional de Fijación y revisión de Precios de Medicamentos de Uso Humano | D14: http://www.salud.gob.ec/consejo-nacional-de-fijacion-y-revision-de-precios-de-medicamentos/
A15: 11 | B15: ECUADOR | C15: Sistema Oficial de Contratación Pública | D15: https://www.compraspublicas.gob.ec/ProcesoContratacion/compras/PC/buscarProceso.cpe?sg=1
A16: 12 | B16: EE.UU. | C16: Center for Medicare and Medicaid Services - CMS | D16: https://www.cms.gov/Medicare/Medicare-Fee-for-Service-Part-B-Drugs/McrPartBDrugAvgSalesPrice/2017ASPFiles.html
... A36: 32 | B36: SUDAFRICA | C36: National Department Of Health | D36: https://www.health.gov.za/nhi-pee/

Sheet MARGEN
A1: Márgenes de ajuste de los precios internacionales
A3: Última actualización: Febrero de 2024
A4: PF: Precio fabricante PM: Precio mayorista Pcompra: precio de compra de droguería (indiferente a quien compra) Pcons: Precio al consumidor
A5: No. | B5: País | C5: Enlace | D5: Margen de ajuste hasta el mayorista o institucional | F5: Margen de ajuste hasta el consumidor | H5: Fecha inicio vigencia
D6: Rango | E6: Márgen | F6: Rango | G6: Márgen**
A7: 1 | B7: ALEMANIA | C7: =HYPERLINK("http://www.gesetze-im-internet.de/ampreisv/BJNR021470980.html","Link") -> Link | D7: PF ≤ € 0,84 | E7: 0.21 | F7: PM ≤ € 1,22 | G7: 0.68 | H7: 42859
D8: € 0,85 ≤ PF ≤ € 0,88 | E8: 0.18 | F8: € 1,23 ≤ PM ≤ € 1,34 | G8: 0.83
D9: €0,89 ≤ PF ≤ €1,70 | E9: 0.2 | F9: €1,35 ≤ PM ≤ €3,88 | G9: 0.62
D10: € 1,71 ≤ PF ≤ € 1,74 | E10: 0.34 | F10: € 3,89 ≤ PM ≤ € 4,22 | G10: 2.41
D11: €1,75 ≤ PF ≤ €2,56 | E11: 0.195 | F11: €4,23 ≤ PM ≤ €7,30 | G11: 0.57
D12: € 2,57 ≤ PF ≤ € 2,63 | E12: 0.5 | F12: € 7,31 ≤ PM ≤ € 8,67 | G12: 4.16
D13: €2,64 ≤ PF ≤ €3,65 | E13: 0.19 | F13: €8,68 ≤ PM ≤ €12,14 | G13: 0.48
D14: € 3,66 ≤ PF ≤ € 3,75 | E14: 0.7 | F14: € 12,15 ≤ PM ≤ € 13,55 | G14: 5.83
D15: €3,76 ≤ PF ≤ €6,03 | E15: 0.185 | F15: €13,56 ≤ PM ≤ €19,42 | G15: 0.43
D16: € 6,04 ≤ PF ≤ € 6,20 | E16: 1.12 | F16: € 19,43 ≤ PM ≤ € 22,57 | G16: 8.35
D17: €6,21 ≤ PF ≤ €9,10 | E17: 0.18 | F17: €22,58 ≤ PM ≤ €29,14 | G17: 0.37
D18: € 9,11 ≤ PF ≤ € 10,92 | E18: 1.64 | F18: € 29,15 ≤ PM ≤ € 35,94 | G18: 10.78
D19: €10,93 ≤ PF ≤ €44,46 | E19: 0.15 | F19: €35,95 ≤ PM ≤ €543,91 | G19: 0.3
D20: € 44,47 ≤ PF ≤ € 55,58 | E20: 6.67 | F20: PM > € 543,92 | G20: 8,263% + € 118,24
D21: €55,59 ≤ PF ≤ €684,76 | E21: 0.12
D22: PF ≥ €684,77 | E22: 3% + € 61,63
A23: 2 | B23: AUSTRALIA | C23: =HYPERLINK("https://www.pbs.gov.au/info/healthpro/explanatory-notes/front/fee","Link 1") -> Link 1 | D23: PF≤ $5.50 | E23: 0.41 | H23: 45292
D24: PF> $5.50≤$720 | E24: 0.0752
D29: PF>$720 | E29: 54.14 | F29: Pcompra < $100 | G29: 4.62 | H29: 45292
F30: $100 ≤ Pcompra ≤ $2000 | G30: $4.62 + [(PM-100)*5%]
F31: Pcompra > $2000 | G31: 0.9962
A32: 3 | B32: BRASIL1 | C32: =HYPERLINK("https://www.gov.br/anvisa/pt-br/assuntos/medicamentos/cmed/precos/arquivos/pdf_conformidade_site_20240207_072034579.pdf/@@download/file","Link 1") -> Link 1 | F32: PF | G32: 0.22 | H32: 45329
C33: =HYPERLINK("https://ppri.goeg.at/sites/ppri.goeg.at/files/inline-files/_Country_Poster_Book%20_final_V2.pdf","Link 2") -> Link 2 | D33: PF | E33: 12%* | H33: 43755
A34: 4 | B34: CANADÁ | C34: =HYPERLINK("https://www.canada.ca/en/patented-medicine-prices-review/services/npduis/analytical-studies/supporting-information/markup-policies-public-drug.html","Link 1") -> Link 1 | D34: PF | E34: 0.09 | H34: 45306
A35: 5 | B35: ESPAÑA | C35: =HYPERLINK("http://www.boe.es/buscar/act.php?id=BOE-A-2008-9291","Link") -> Link | D35: PF ≤ €91,63 | E35: 0.076 | F35: PF ≤ €91,63 | G35: 0.279 | H35: 44895
D36: PF > €91,63 | E36: 7.54 | F36: €91,63 < PF ≤ €200 | G36: 38.37
F37: €200 < PF ≤ €500 | G37: 43.37
F38: PF > €500 | G38: 48.37
A39: 6 | B39: FRANCIA | C39: =HYPERLINK("https://www.legifrance.gouv.fr/affichTexte.do?cidTexte=JORFTEXT000000843609","Link") -> Link | D39: PF ≤ €468,97 | E39: 0.0693 | F39: PF ≤ €1,91 | G39: 0.1 | H39: 1/04/2022
F40: €1,92 ≤ PF ≤ €22,90 | G40: 0.07
D41: PF > €468,67 | E41: 0 | F41: €22,91 ≤ PF ≤ €150 | G41: 0.055
F42: €150,01 ≤ PF ≤ €1930 | G42: 0.05
F43: PF > €1930 | G43: 0
A44: 7 | B44: GRECIA | C44: =HYPERLINK("https://sfee.gr/wp-content/uploads/2015/04/Ministerial-Decision-Pricing-of-Medicines.pdf","Link") -> Link | D44: PF | E44: 0.054 | F44: PM | G44: 0.35
A45: 8 | B45: INDIA | C45: =HYPERLINK("https://www.nppaindia.nic.in/wp-content/uploads/2018/12/DPCO2013_03082016.pdf","Link") -> Link | F45: Pcompra | G45: 0.16 | H45: 42451
...
